OrderBookSim/OrderBookSim/Outputs/Log1359734770.txt
0--INFO	Added rule
0--INFO	Added rule
0--INFO	Added rule
0--INFO	Added rule
0--INFO	Added trader: Trader[0]: Cash[$15316.02], Holding:GOOG[10256], PositionCash[$15316.02], PositionHolding:GOOG[10256]
0--INFO	Added trader: Trader[1]: Cash[$17865.54], Holding:GOOG[5156], PositionCash[$17865.54], PositionHolding:GOOG[5156]
0--INFO	Added trader: Trader[2]: Cash[$7710.20], Holding:GOOG[17194], PositionCash[$7710.20], PositionHolding:GOOG[17194]
0--INFO	Added trader: Trader[3]: Cash[$7802.36], Holding:GOOG[4147], PositionCash[$7802.36], PositionHolding:GOOG[4147]
0--INFO	Added trader: Trader[4]: Cash[$17979.67], Holding:GOOG[6044], PositionCash[$17979.67], PositionHolding:GOOG[6044]
0--INFO	Added trader: Trader[5]: Cash[$17556.08], Holding:GOOG[15329], PositionCash[$17556.08], PositionHolding:GOOG[15329]
0--INFO	Added trader: Trader[6]: Cash[$7273.78], Holding:GOOG[4085], PositionCash[$7273.78], PositionHolding:GOOG[4085]
0--INFO	Added trader: Trader[7]: Cash[$7047.94], Holding:GOOG[5438], PositionCash[$7047.94], PositionHolding:GOOG[5438]
0--INFO	Added trader: Trader[8]: Cash[$19620.96], Holding:GOOG[4780], PositionCash[$19620.96], PositionHolding:GOOG[4780]
0--INFO	Added trader: Trader[9]: Cash[$8516.50], Holding:GOOG[14280], PositionCash[$8516.50], PositionHolding:GOOG[14280]
0--INFO	Added trader: Trader[10]: Cash[$6808.68], Holding:GOOG[18047], PositionCash[$6808.68], PositionHolding:GOOG[18047]
0--INFO	Added trader: Trader[11]: Cash[$7539.29], Holding:GOOG[18758], PositionCash[$7539.29], PositionHolding:GOOG[18758]
0--INFO	Added trader: Trader[12]: Cash[$12698.14], Holding:GOOG[5369], PositionCash[$12698.14], PositionHolding:GOOG[5369]
0--INFO	Added trader: Trader[13]: Cash[$3904.54], Holding:GOOG[12997], PositionCash[$3904.54], PositionHolding:GOOG[12997]
0--INFO	Added trader: Trader[14]: Cash[$3476.67], Holding:GOOG[15203], PositionCash[$3476.67], PositionHolding:GOOG[15203]
0--INFO	Added trader: Trader[15]: Cash[$1333.05], Holding:GOOG[12536], PositionCash[$1333.05], PositionHolding:GOOG[12536]
0--INFO	Added trader: Trader[16]: Cash[$5888.24], Holding:GOOG[7590], PositionCash[$5888.24], PositionHolding:GOOG[7590]
0--INFO	Added trader: Trader[17]: Cash[$16339.00], Holding:GOOG[6737], PositionCash[$16339.00], PositionHolding:GOOG[6737]
0--INFO	Added trader: Trader[18]: Cash[$654.32], Holding:GOOG[1311], PositionCash[$654.32], PositionHolding:GOOG[1311]
0--INFO	Added trader: Trader[19]: Cash[$16232.18], Holding:GOOG[4373], PositionCash[$16232.18], PositionHolding:GOOG[4373]
0--INFO	Added trader: Trader[20]: Cash[$5694.14], Holding:GOOG[14777], PositionCash[$5694.14], PositionHolding:GOOG[14777]
0--INFO	Added trader: Trader[21]: Cash[$16962.80], Holding:GOOG[15344], PositionCash[$16962.80], PositionHolding:GOOG[15344]
0--INFO	Added trader: Trader[22]: Cash[$5815.00], Holding:GOOG[5623], PositionCash[$5815.00], PositionHolding:GOOG[5623]
0--INFO	Added trader: Trader[23]: Cash[$15566.27], Holding:GOOG[19191], PositionCash[$15566.27], PositionHolding:GOOG[19191]
0--INFO	Added trader: Trader[24]: Cash[$14812.46], Holding:GOOG[6212], PositionCash[$14812.46], PositionHolding:GOOG[6212]
0--INFO	Added trader: Trader[25]: Cash[$2041.08], Holding:GOOG[948], PositionCash[$2041.08], PositionHolding:GOOG[948]
0--INFO	Added trader: Trader[26]: Cash[$4848.78], Holding:GOOG[5415], PositionCash[$4848.78], PositionHolding:GOOG[5415]
0--INFO	Added trader: Trader[27]: Cash[$13953.67], Holding:GOOG[19449], PositionCash[$13953.67], PositionHolding:GOOG[19449]
0--INFO	Added trader: Trader[28]: Cash[$19132.66], Holding:GOOG[3632], PositionCash[$19132.66], PositionHolding:GOOG[3632]
0--INFO	Added trader: Trader[29]: Cash[$6474.20], Holding:GOOG[4934], PositionCash[$6474.20], PositionHolding:GOOG[4934]
0--INFO	Added trader: Trader[30]: Cash[$9710.99], Holding:GOOG[10560], PositionCash[$9710.99], PositionHolding:GOOG[10560]
0--INFO	Added trader: Trader[31]: Cash[$13413.50], Holding:GOOG[14319], PositionCash[$13413.50], PositionHolding:GOOG[14319]
0--INFO	Added trader: Trader[32]: Cash[$5243.69], Holding:GOOG[6202], PositionCash[$5243.69], PositionHolding:GOOG[6202]
0--INFO	Added trader: Trader[33]: Cash[$15316.02], Holding:GOOG[10256], PositionCash[$15316.02], PositionHolding:GOOG[10256]
0--INFO	Added trader: Trader[34]: Cash[$15316.02], Holding:GOOG[10256], PositionCash[$15316.02], PositionHolding:GOOG[10256]
0--INFO	Added trader: Trader[35]: Cash[$15316.02], Holding:GOOG[10256], PositionCash[$15316.02], PositionHolding:GOOG[10256]
0--INFO	Added trader: Trader[36]: Cash[$15316.02], Holding:GOOG[10256], PositionCash[$15316.02], PositionHolding:GOOG[10256]
0--INFO	Added trader: Trader[37]: Cash[$15316.02], Holding:GOOG[10256], PositionCash[$15316.02], PositionHolding:GOOG[10256]
0--INFO	Added trader: Trader[38]: Cash[$15316.02], Holding:GOOG[10256], PositionCash[$15316.02], PositionHolding:GOOG[10256]
0--INFO	Added trader: Trader[39]: Cash[$15316.02], Holding:GOOG[10256], PositionCash[$15316.02], PositionHolding:GOOG[10256]
0--INFO	Added trader: Trader[40]: Cash[$15316.02], Holding:GOOG[10256], PositionCash[$15316.02], PositionHolding:GOOG[10256]
0--INFO	Added trader: Trader[41]: Cash[$15316.02], Holding:GOOG[10256], PositionCash[$15316.02], PositionHolding:GOOG[10256]
0--INFO	Added trader: Trader[42]: Cash[$15316.02], Holding:GOOG[10256], PositionCash[$15316.02], PositionHolding:GOOG[10256]
0--INFO	Added trader: Trader[43]: Cash[$15316.02], Holding:GOOG[10256], PositionCash[$15316.02], PositionHolding:GOOG[10256]
0--INFO	Added trader: Trader[44]: Cash[$15316.02], Holding:GOOG[10256], PositionCash[$15316.02], PositionHolding:GOOG[10256]
0--INFO	Added trader: Trader[45]: Cash[$15316.02], Holding:GOOG[10256], PositionCash[$15316.02], PositionHolding:GOOG[10256]
0--INFO	Added trader: Trader[46]: Cash[$15316.02], Holding:GOOG[10256], PositionCash[$15316.02], PositionHolding:GOOG[10256]
0--INFO	Added trader: Trader[47]: Cash[$15316.02], Holding:GOOG[10256], PositionCash[$15316.02], PositionHolding:GOOG[10256]
0--INFO	Added trader: Trader[48]: Cash[$1000000.00], Holding:GOOG[10000000], PositionCash[$1000000.00], PositionHolding:GOOG[10000000]
0--INFO	Added trader: Trader[49]: Cash[$1000000.00], Holding:GOOG[10000000], PositionCash[$1000000.00], PositionHolding:GOOG[10000000]
68--INFO	Enqueued order: Price: 2147483647.00, Volume: 710, Type: BUY, Market Order: 1, Participant: 33, Stock:[ID: 0, Symbol: GOOG], Time: 68, OrderNumber: 0
68--INFO	Enqueued order: Price: 2147483647.00, Volume: 386, Type: BUY, Market Order: 1, Participant: 34, Stock:[ID: 0, Symbol: GOOG], Time: 68, OrderNumber: 1
68--INFO	Enqueued order: Price: 2147483647.00, Volume: 208, Type: BUY, Market Order: 1, Participant: 35, Stock:[ID: 0, Symbol: GOOG], Time: 68, OrderNumber: 2
68--INFO	Enqueued order: Price: 0.00, Volume: 500, Type: SELL, Market Order: 1, Participant: 36, Stock:[ID: 0, Symbol: GOOG], Time: 68, OrderNumber: 3
68--INFO	Enqueued order: Price: 2147483647.00, Volume: 364, Type: BUY, Market Order: 1, Participant: 37, Stock:[ID: 0, Symbol: GOOG], Time: 68, OrderNumber: 4
68--INFO	Enqueued order: Price: 1.03, Volume: 272, Type: SELL, Market Order: 0, Participant: 38, Stock:[ID: 0, Symbol: GOOG], Time: 68, OrderNumber: 5
68--INFO	Enqueued order: Price: 0.00, Volume: 271, Type: SELL, Market Order: 1, Participant: 39, Stock:[ID: 0, Symbol: GOOG], Time: 68, OrderNumber: 6
68--INFO	Enqueued order: Price: 0.00, Volume: 341, Type: SELL, Market Order: 1, Participant: 40, Stock:[ID: 0, Symbol: GOOG], Time: 68, OrderNumber: 7
68--INFO	Enqueued order: Price: 2147483647.00, Volume: 938, Type: BUY, Market Order: 1, Participant: 41, Stock:[ID: 0, Symbol: GOOG], Time: 68, OrderNumber: 8
68--INFO	Enqueued order: Price: 2147483647.00, Volume: 247, Type: BUY, Market Order: 1, Participant: 42, Stock:[ID: 0, Symbol: GOOG], Time: 68, OrderNumber: 9
68--INFO	Enqueued order: Price: 0.00, Volume: 174, Type: SELL, Market Order: 1, Participant: 43, Stock:[ID: 0, Symbol: GOOG], Time: 68, OrderNumber: 10
68--INFO	Enqueued order: Price: 2147483647.00, Volume: 627, Type: BUY, Market Order: 1, Participant: 44, Stock:[ID: 0, Symbol: GOOG], Time: 68, OrderNumber: 11
